Workbook

Sheet Instructions
A1: A3 Partner Portal Asset Workbook
A3: Purpose | B3: Single source of truth for branding opportunities with separate public-facing and internal operational fields.
A4: Use this workbook | B4: 1) Enter each branding opportunity once in Asset_Master. 2) Tie all photos to one Asset ID. 3) Use Portal_Export for the website/deck. 4) Use Internal_Intake_Email and NetSuite_Export for ops.
A5: Golden rule | B5: One row per physical branding opportunity, not one row per photo.
A6: Public vs internal | B6: Public sheets must not expose measurements, install notes, supplier cost, commissions, or marked-up measurement photos.
A7: Photo standard | B7: For each Asset ID, store one clean public photo, one internal marked measurement photo, and optional internal reference angles.
A8: Suggested ID format | B8: SW-BENCH-001, WM-WALL-007, MM-BARFRONT-003
A9: Workflow | B9: User selects Asset ID on portal -> backend enriches with hidden internal fields -> your intake email arrives with dimensions and notes already attached.
A10: File naming | B10: Use Asset ID in every image filename to prevent mismatch.

Sheet Setup_Lists
A1: Dropdown and Logic Lists
A3: List Name | B3: Value | C3: Notes | E3: Surface Material | F3: Default Recommended Applications | G3: Avoid / Caution | H3: Notes
A4: Partner | B4: Swarm | E4: Wood | F4: Decal | Fabric Wrap | Rigid Sign | G4: Check surface smoothness and prep | H4: Great for benches, panels, facias
A5: Partner | B5: Wynwood Marketplace | E5: Glass | F5: Decal | Window Perf | Frosted Vinyl | G5: Confirm visibility rules | H5: Use for storefronts, windows, doors
A6: Partner | B6: Moon Miami | E6: Metal | F6: Decal | Magnetic | Rigid Sign | G6: Check temperature and curvature | H6: Best when smooth and clean
A7: Partner | B7: Move Miami | E7: Concrete | F7: Banner | Rigid Sign | G7: Direct adhesion may fail | H7: Use mounted solutions when textured
A8: Partner | B8: Other | E8: Painted Wall | F8: Decal | Banner | Rigid Sign | G8: Test adhesion first | H8: Texture and paint quality matter
E9: Drywall | F9: Decal | Banner | Rigid Sign | G9: Avoid damage on removal | H9: Temporary graphics may need low-tack
A10: Asset Type | B10: Bench | E10: Acrylic | F10: Decal | Frosted Vinyl | Rigid Sign | G10: Avoid scratching | H10: Premium sponsor areas
A11: Asset Type | B11: Wall | E11: Mesh/Fence | F11: Banner | Mesh Banner | G11: Wind load matters | H11: Good for exterior activations
A12: Asset Type | B12: Window | E12: Fabric-Compatible Frame | F12: Fabric Wrap | Fabric Graphic | G12: Confirm frame hardware | H12: Ideal for soft signage systems
A13: Asset Type | B13: Bar Front | E13: Floor Surface | F13: Floor Decal | G13: High traffic and slip rating required | H13: Always laminate appropriately
A14: Asset Type | B14: Fence | E14: Other | F14: Needs Review | G14: Manual review needed
A15: Asset Type | B15: Column
A16: Asset Type | B16: Floor
A17: Asset Type | B17: Table
A18: Asset Type | B18: Cooler
A19: Asset Type | B19: Stage Element
A20: Asset Type | B20: Entry Feature
A21: Asset Type | B21: Ceiling/Hanging
A22: Asset Type | B22: Other
A24: Zone | B24: Entrance
A25: Zone | B25: Patio
A26: Zone | B26: Stage
A27: Zone | B27: Bar
... A90: NetSuite Category | B90: Other

Sheet Asset_Master
A1: Asset ID | B1: Partner | C1: Venue Name | D1: Zone / Area | E1: Asset Name | F1: Asset Type | G1: Public Title | H1: Public Description | I1: Public Photo URL | J1: Internal Marked Photo URL | K1: Internal Ref Photo URL 2 | L1: Internal Ref Photo URL 3 | M1: Surface Material | N1: Environment | O1: Recommended Public Applications | P1: Alternate Applications | Q1: Primary Recommended Application | R1: Length | S1: Width | T1: Height | U1: Measurement Unit | V1: Sq Ft | W1: Orientation | X1: Visibility Tier | Y1: Public Status | Z1: Public Deck Include? | AA1: Portal Visible? | AB1: NetSuite Include? | AC1: Install Notes | AD1: Production Notes | AE1: Design Needed? | AF1: Public Use Case | AG1: NetSuite Item Name | AH1: NetSuite Category | AI1: Internal Pricing Notes | AJ1: Commission Eligible? | AK1: Ops Owner | AL1: Backend Hidden Payload Preview
A2: SW-BENCH-001 | B2: Swarm | C2: Swarm Main Venue | D2: Patio | E2: Patio Bench A | F2: Bench | G2: Patio Wood Bench | H2: High visibility sponsor or event branding surface near seating. | I2: https://example.com/SW-BENCH-001-public.jpg | J2: https://example.com/SW-BENCH-001-marked.jpg | K2: https://example.com/SW-BENCH-001-ref-02.jpg | M2: Wood | N2: Covered Outdoor | O2: Decal | Fabric Wrap | P2: Rigid Sign | Q2: Decal | R2: 72 | S2: 18 | U2: in | V2: =IF(OR(R2="",S2=""),"",IF(U2="in",R2*S2/144,R2*S2)) | W2: Horizontal | X2: High | Y2: Available | Z2: Yes | AA2: Yes | AB2: Yes | AC2: Confirm surface prep before install. | AD2: Outdoor-safe print and laminate recommended. | AE2: Yes | AF2: Ideal for sponsor logo, QR moment, seasonal campaign. | AG2: SW Bench 001 Graphic | AH2: Graphics | AI2: Use for early pricing basis only. | AJ2: Yes | AK2: Alyssa | AL2: =IF(A2="","","AssetID="&A2&" | Venue="&C2&" | Zone="&D2&" | Dimensions="&R2&"x"&S2&IF(T2<>"","x"&T2,"")&" "&U2&" | Surface="&M2&" | PrimaryApp="&Q2&" | Status="&Y2&" | InstallNotes="&AC2)
A3: WM-WALL-007 | B3: Wynwood Marketplace | C3: Wynwood Marketplace | D3: Entrance | E3: Entry Wall Left | F3: Wall | G3: Entrance Branding Wall | H3: Strong first-impression wall for campaign messaging or event welcome moment. | I3: https://example.com/WM-WALL-007-public.jpg | J3: https://example.com/WM-WALL-007-marked.jpg | M3: Painted Wall | N3: Indoor | O3: Decal | Banner | P3: Rigid Sign | Q3: Decal | R3: 120 | S3: 96 | U3: in | V3: =IF(OR(R3="",S3=""),"",IF(U3="in",R3*S3/144,R3*S3)) | W3: Horizontal | X3: High | Y3: Available | Z3: Yes | AA3: Yes | AB3: Yes | AC3: Texture test before install. | AD3: Consider seam placement and removal method. | AE3: Yes | AF3: Great for event title, sponsor lockup, step-in photo zone. | AG3: WM Wall 007 Graphic | AH3: Graphics | AJ3: Yes | AK3: Alyssa | AL3: =IF(A3="","","AssetID="&A3&" | Venue="&C3&" | Zone="&D3&" | Dimensions="&R3&"x"&S3&IF(T3<>"","x"&T3,"")&" "&U3&" | Surface="&M3&" | PrimaryApp="&Q3&" | Status="&Y3&" | InstallNotes="&AC3)
A4: WM-TABLE-001 | B4: Wynwood Marketplace | C4: Wynwood Marketplace | D4: Covered Patio | E4: Rustic Barrel Cocktail Table | F4: Cocktail Table | G4: Rustic Cocktail Table Branding | H4: Compact branded cocktail table opportunity in covered patio seating area. | J4: DD192C20-247A-4C29-BF1C-9C83790F99B6.jpeg | M4: Wood and glass | N4: Covered Outdoor | O4: Decal | Table Topper | P4: Rigid Sign | Q4: Decal | R4: 30 | S4: 20 | U4: in | V4: =IF(OR(R4="",S4=""),"",IF(U4="in",R4*S4/144,R4*S4)) | W4: Horizontal | X4: Medium | Y4: Internal Review | Z4: No | AA4: No | AB4: Yes | AC4: Top appears to be circular glass insert with wood rim. Confirm whether branding applies to top insert only or side band as secondary option. | AD4: Use removable or permanent tabletop vinyl depending program length. Side band wrap may require field verification. | AE4: Yes | AF4: Best for tabletop sponsor lockup, QR, or drink brand moment. | AG4: WM Rustic Cocktail Table Graphic | AH4: Graphics | AI4: Quote as custom tabletop graphic with site verification. | AJ4: Yes | AK4: Alyssa | AL4: =IF(A4="","","AssetID="&A4&" | Venue="&C4&" | Zone="&D4&" | Dimensions="&R4&"x"&S4&IF(T4<>"","x"&T4,"")&" "&U4&" | Surface="&M4&" | PrimaryApp="&Q4&" | Status="&Y4&" | InstallNotes="&AC4)
A5: WM-PICNIC-001 | B5: Wynwood Marketplace | C5: Wynwood Marketplace | D5: Open Turf Seating | E5: Red Picnic Table | F5: Picnic Table | G5: Picnic Table Branding Opportunity | H5: High visibility picnic table in open seating area suitable for tabletop and bench branding. | J5: C8E48337-7F82-416A-B38E-C25AD7606F89.jpeg | M5: Painted wood | N5: Outdoor | O5: Decal | Partial Wrap | P5: Rigid Sign | Q5: Decal | R5: 71 | S5: 28 | U5: in | V5: =IF(OR(R5="",S5=""),"",IF(U5="in",R5*S5/144,R5*S5)) | W5: Horizontal | X5: High | Y5: Internal Review | Z5: No | AA5: No | AB5: Yes | AC5: Primary measurable branding surface is tabletop. Bench tops measure approximately 11 in wide and can support supplemental graphics. | AD5: Outdoor laminate required. Confirm whether full table set or tabletop only is approved for branding. | AE5: Yes | AF5: Great for sponsor takeover, food and beverage partner, or event-specific seating branding. | AG5: WM Picnic Table Graphic | AH5: Graphics | AI5: Price tabletop primary and bench add-on separately. | AJ5: Yes | AK5: Alyssa | AL5: =IF(A5="","","AssetID="&A5&" | Venue="&C5&" | Zone="&D5&" | Dimensions="&R5&"x"&S5&IF(T5<>"","x"&T5,"")&" "&U5&" | Surface="&M5&" | PrimaryApp="&Q5&" | Status="&Y5&" | InstallNotes="&AC5)
A6: WM-CAFE-001 | B6: Wynwood Marketplace | C6: Wynwood Marketplace | D6: Patio Seating | E6: Square Café Tables Set | F6: Table Set | G6: Café Table Top Branding Set | H6: Repeatable café table branding program across patio seating cluster. | J6: F9DBF46E-F471-43BE-A184-6CE257A5F511.jpeg | M6: Composite table top and metal base | N6: Outdoor | O6: Decal | Table Topper | P6: Rigid Sign | Q6: Decal | R6: 23 | S6: 23 | U6: in | V6: =IF(OR(R6="",S6=""),"",IF(U6="in",R6*S6/144,R6*S6)) | W6: Horizontal | X6: High | Y6: Internal Review | Z6: No | AA6: No | AB6: Yes | AC6: Image notes 34 total tables. Confirm count on site before quoting production quantity. | AD6: Recommended as repeatable tabletop decal program. Consider anti-slip and outdoor laminate if beverage service area. | AE6: Yes | AF6: Ideal for repeated sponsor presence across multiple guest touchpoints. | AG6: WM Cafe Table Top Graphic | AH6: Graphics | AI6: Build quote per unit and extended quantity for 34 tables. | AJ6: Yes | AK6: Alyssa | AL6: =IF(A6="","","AssetID="&A6&" | Venue="&C6&" | Zone="&D6&" | Dimensions="&R6&"x"&S6&IF(T6<>"","x"&T6,"")&" "&U6&" | Surface="&M6&" | PrimaryApp="&Q6&" | Status="&Y6&" | InstallNotes="&AC6)
A7: WM-BENCH-001 | B7: Wynwood Marketplace | C7: Wynwood Marketplace | D7: Covered Patio | E7: Built In Wood Bench | F7: Bench | G7: Built In Bench Branding Opportunity | H7: Built in bench with multiple visible panels for sponsor or zone branding in covered patio area. | J7: 9A689A0F-796B-4F4B-950C-49495DA31FEA.jpeg | M7: Painted wood | N7: Covered Outdoor | O7: Decal | Fabric Wrap | P7: Rigid Sign | Q7: Decal | R7: 25.5 | S7: 19 | U7: in | V7: =IF(OR(R7="",S7=""),"",IF(U7="in",R7*S7/144,R7*S7)) | W7: Horizontal | X7: Medium | Y7: Internal Review | Z7: No | AA7: No | AB7: Yes | AC7: Primary front face appears 25.5 in x 19 in. Additional measured references include seat depth 17 in, back height 19 in, overall height 38 in, top cap depth 8.5 in. | AD7: Confirm whether branding is limited to front face, side panel, or full wrap treatment before estimating. | AE7: Yes | AF7: Useful for lounge sponsor integration or branded seating zone accents. | AG7: WM Built In Bench Graphic | AH7: Graphics | AI7: Field verify exact printable faces if wrap requested. | AJ7: Yes | AK7: Alyssa | AL7: =IF(A7="","","AssetID="&A7&" | Venue="&C7&" | Zone="&D7&" | Dimensions="&R7&"x"&S7&IF(T7<>"","x"&T7,"")&" "&U7&" | Surface="&M7&" | PrimaryApp="&Q7&" | Status="&Y7&" | InstallNotes="&AC7)
A8: WM-WALL-001 | B8: Wynwood Marketplace | C8: Wynwood Marketplace | D8: Covered Patio Backdrop | E8: Faux Hedge Wall | F8: Backdrop Wall | G8: Patio Hedge Backdrop Branding | H8: Large faux hedge backdrop wall suitable for event branding, sponsor logo display, or step-in photo moment. | J8: 98960501-39F9-46AE-8C3A-BC27514CBF26.jpeg | M8: Artificial hedge / textured wall | N8: Covered Outdoor | O8: Banner | Fabric Graphic | Rigid Sign | P8: Decal | Q8: Fabric Graphic | R8: 112 | S8: 86 | U8: in | V8: =IF(OR(R8="",S8=""),"",IF(U8="in",R8*S8/144,R8*S8)) | W8: Horizontal | X8: High | Y8: Internal Review | Z8: No | AA8: No | AB8: Yes | AC8: Textured hedge surface is not ideal for direct decal. Recommend mounted signage, suspended banner, or fabric overlay system. | AD8: Confirm mounting method and venue restrictions. Use lightweight materials and removable hardware. | AE8: Yes | AF8: Strong sponsor backdrop, photo op, or welcome moment. | AG8: WM Hedge Wall Branding | AH8: Signage | AI8: Estimate with install hardware and removal method. | AJ8: Yes | AK8: Alyssa | AL8: =IF(A8="","","AssetID="&A8&" | Venue="&C8&" | Zone="&D8&" | Dimensions="&R8&"x"&S8&IF(T8<>"","x"&T8,"")&" "&U8&" | Surface="&M8&" | PrimaryApp="&Q8&" | Status="&Y8&" | InstallNotes="&AC8)
A9: WM-WALKWAY-001 | B9: Wynwood Marketplace | C9: Wynwood Marketplace | D9: Main Deck Runway | E9: Deck Walkway Strip | F9: Walkway | G9: Main Deck Walkway Branding | H9: Linear deck walkway that can support directional or experiential ground branding. | J9: D22B7048-D0B5-4545-9864-6775005188E4.jpeg | M9: Wood deck flooring | N9: Outdoor | O9: Floor Decal | Directional Graphics | P9: Banner | Q9: Floor Decal | R9: 24 | U9: ft | V9: =IF(OR(R9="",S9=""),"",IF(U9="in",R9*S9/144,R9*S9)) | W9: Horizontal | X9: High | Y9: Needs Field Verification | Z9: No | AA9: No | AB9: Yes | AC9: Image provides 24 ft run length only. Width still needs to be measured before production sizing. | AD9: Use outdoor slip-rated floor graphic system only if venue permits. Confirm weather exposure and traction requirements. | AE9: Yes | AF9: Ideal for sponsor path, directional messaging, or branded entry journey. | AG9: WM Walkway Floor Graphic | AH9: Floor Graphics | AI9: Do not quote final square footage until width is captured. | AJ9: Yes | AK9: Alyssa | AL9: =IF(A9="","","AssetID="&A9&" | Venue="&C9&" | Zone="&D9&" | Dimensions="&R9&"x"&S9&IF(T9<>"","x"&T9,"")&" "&U9&" | Surface="&M9&" | PrimaryApp="&Q9&" | Status="&Y9&" | InstallNotes="&AC9)
A10: WM-ENTRY-001 | B10: Wynwood Marketplace | C10: Wynwood Marketplace | D10: Main Entry Span | E10: Entry Opening Span | F10: Entrance | G10: Main Entry Span Branding | H10: Primary entry span that may support overhead or gateway branding treatment. | J10: 38C40E77-7910-420D-AD2D-8032B407B256.jpeg | M10: Mixed structural opening | N10: Outdoor | O10: Banner | Overhead Signage | P10: Rigid Sign | Q10: Banner | R10: 17.2 | U10: ft | V10: =IF(OR(R10="",S10=""),"",IF(U10="in",R10*S10/144,R10*S10)) | W10: Horizontal | X10: High | Y10: Needs Field Verification | Z10: No | AA10: No | AB10: Yes | AC10: Image shows width of approximately 17.2 ft only. Height and approved attachment points still need confirmation. | AD10: Suitable for overhead banner or gateway header if permitted. Engineering or attachment review may be required. | AE10: Yes | AF10: Best for welcome message, event title, or presenting sponsor entry branding. | AG10: WM Entry Span Banner | AH10: Banners | AI10: Pending venue approval and attachment method confirmation. | AJ10: Yes | AK10: Alyssa | AL10: =IF(A10="","","AssetID="&A10&" | Venue="&C10&" | Zone="&D10&" | Dimensions="&R10&"x"&S10&IF(T10<>"","x"&T10,"")&" "&U10&" | Surface="&M10&" | PrimaryApp="&Q10&" | Status="&Y10&" | InstallNotes="&AC10)
A11: WM-WALL-002 | B11: Wynwood Marketplace | C11: Wynwood Marketplace | D11: Exterior Lawn Edge | E11: Wynwood Skate Container Wall | F11: Container Wall | G11: Large Exterior Container Wall Branding | H11: Large exterior shipping container wall with substantial scale for mural, campaign, or sponsor takeover. | J11: 74DD7AF8-B531-45FD-A893-E46484A34057.jpeg | M11: Painted metal container | N11: Outdoor | O11: Decal | Full Wall Wrap | Banner | P11: Rigid Sign | Q11: Full Wall Wrap | R11: 40 | S11: 16 | U11: ft | V11: =IF(OR(R11="",S11=""),"",IF(U11="in",R11*S11/144,R11*S11)) | W11: Horizontal | X11: High | Y11: Internal Review | Z11: No | AA11: No | AB11: Yes | AC11: Existing artwork on wall indicates venue approval workflow will be required before any replacement, overlay, or temporary takeover. | AD11: Large-format outdoor material and install planning required. Confirm whether full mural replacement, temporary overlay, or sponsor panel approach is allowed. | AE11: Yes | AF11: Premium takeover surface for major sponsor, headline event, or long-range visibility campaign. | AG11: WM Container Wall Wrap | AH11: Graphics | AI11: High-value large-format opportunity with permitting/approval considerations. | AJ11: Yes | AK11: Alyssa | AL11: =IF(A11="","","AssetID="&A11&" | Venue="&C11&" | Zone="&D11&" | Dimensions="&R11&"x"&S11&IF(T11<>"","x"&T11,"")&" "&U11&" | Surface="&M11&" | PrimaryApp="&Q11&" | Status="&Y11&" | InstallNotes="&AC11)
A12: WM-PLANTER-001 | B12: Wynwood Marketplace | C12: Wynwood Marketplace | D12: Exterior Edge | E12: Square Planter Box | F12: Planter | G12: Planter Box Branding Opportunity | H12: Freestanding planter box that can support compact sponsor or wayfinding graphics on visible side panels. | J12: D04A8A05-90FD-4169-B135-8D61C770A1AB.jpeg | M12: Wood | N12: Outdoor | O12: Decal | Rigid Panel | P12: Fabric Wrap | Q12: Decal | R12: 43 | S12: 43 | U12: in | V12: =IF(OR(R12="",S12=""),"",IF(U12="in",R12*S12/144,R12*S12)) | W12: Square | X12: Medium | Y12: Internal Review | Z12: No | AA12: No | AB12: Yes | AC12: Visible side panels appear approximately 43 in x 43 in. Top rim is noted at 6 in and may affect full-face graphic coverage. | AD12: Best treated as side-panel graphics on one or multiple faces. Confirm total number of matching planter units on site. | AE12: Yes | AF12: Good for repeating sponsor presence, directional branding, or zone identification. | AG12: WM Planter Box Graphic | AH12: Graphics | AI12: Quote per face and multiply by approved number of units. | AJ12: Yes | AK12: Alyssa | AL12: =IF(A12="","","AssetID="&A12&" | Venue="&C12&" | Zone="&D12&" | Dimensions="&R12&"x"&S12&IF(T12<>"","x"&T12,"")&" "&U12&" | Surface="&M12&" | PrimaryApp="&Q12&" | Status="&Y12&" | InstallNotes="&AC12)
A13: WM-BAR-001 | B13: Wynwood Marketplace | C13: Wynwood Marketplace | D13: Tent Activation Area | E13: Wood Front Bar | F13: Bar Front | G13: Portable Bar Front Branding | H13: Portable wood bar with large front face suitable for branded bar takeover or sponsor messaging. | J13: A3A9D994-4266-4A50-B41D-ECDD8F6290A2.jpeg | M13: Wood | N13: Covered Outdoor | O13: Decal | Fabric Wrap | Rigid Sign | P13: Banner | Q13: Decal | R13: 75 | S13: 48 | U13: in | V13: =IF(OR(R13="",S13=""),"",IF(U13="in",R13*S13/144,R13*S13)) | W13: Horizontal | X13: High | Y13: Internal Review | Z13: No | AA13: No | AB13: Yes | AC13: Primary front branding face appears 75 in x 48 in. Side depth is 19 in and may support wrap continuation if requested. | AD13: Strong candidate for front-face decal or partial wrap. Verify whether all bars are identical and count total units available. | AE13: Yes | AF13: Ideal for beverage sponsor, branded service point, or event feature activation. | AG13: WM Portable Bar Graphic | AH13: Graphics | AI13: Quote front-face primary with side-wrap option as add-on. | AJ13: Yes | AK13: Alyssa | AL13: =IF(A13="","","AssetID="&A13&" | Venue="&C13&" | Zone="&D13&" | Dimensions="&R13&"x"&S13&IF(T13<>"","x"&T13,"")&" "&U13&" | Surface="&M13&" | PrimaryApp="&Q13&" | Status="&Y13&" | InstallNotes="&AC13)
V14: =IF(OR(R14="",S14=""),"",IF(U14="in",R14*S14/144,R14*S14)) | AL14: =IF(A14="","","AssetID="&A14&" | Venue="&C14&" | Zone="&D14&" | Dimensions="&R14&"x"&S14&IF(T14<>"","x"&T14,"")&" "&U14&" | Surface="&M14&" | PrimaryApp="&Q14&" | Status="&Y14&" | InstallNotes="&AC14)
V15: =IF(OR(R15="",S15=""),"",IF(U15="in",R15*S15/144,R15*S15)) | AL15: =IF(A15="","","AssetID="&A15&" | Venue="&C15&" | Zone="&D15&" | Dimensions="&R15&"x"&S15&IF(T15<>"","x"&T15,"")&" "&U15&" | Surface="&M15&" | PrimaryApp="&Q15&" | Status="&Y15&" | InstallNotes="&AC15)
V16: =IF(OR(R16="",S16=""),"",IF(U16="in",R16*S16/144,R16*S16)) | AL16: =IF(A16="","","AssetID="&A16&" | Venue="&C16&" | Zone="&D16&" | Dimensions="&R16&"x"&S16&IF(T16<>"","x"&T16,"")&" "&U16&" | Surface="&M16&" | PrimaryApp="&Q16&" | Status="&Y16&" | InstallNotes="&AC16)
V17: =IF(OR(R17="",S17=""),"",IF(U17="in",R17*S17/144,R17*S17)) | AL17: =IF(A17="","","AssetID="&A17&" | Venue="&C17&" | Zone="&D17&" | Dimensions="&R17&"x"&S17&IF(T17<>"","x"&T17,"")&" "&U17&" | Surface="&M17&" | PrimaryApp="&Q17&" | Status="&Y17&" | InstallNotes="&AC17)
V18: =IF(OR(R18="",S18=""),"",IF(U18="in",R18*S18/144,R18*S18)) | AL18: =IF(A18="","","AssetID="&A18&" | Venue="&C18&" | Zone="&D18&" | Dimensions="&R18&"x"&S18&IF(T18<>"","x"&T18,"")&" "&U18&" | Surface="&M18&" | PrimaryApp="&Q18&" | Status="&Y18&" | InstallNotes="&AC18)
V19: =IF(OR(R19="",S19=""),"",IF(U19="in",R19*S19/144,R19*S19)) | AL19: =IF(A19="","","AssetID="&A19&" | Venue="&C19&" | Zone="&D19&" | Dimensions="&R19&"x"&S19&IF(T19<>"","x"&T19,"")&" "&U19&" | Surface="&M19&" | PrimaryApp="&Q19&" | Status="&Y19&" | InstallNotes="&AC19)
V20: =IF(OR(R20="",S20=""),"",IF(U20="in",R20*S20/144,R20*S20)) | AL20: =IF(A20="","","AssetID="&A20&" | Venue="&C20&" | Zone="&D20&" | Dimensions="&R20&"x"&S20&IF(T20<>"","x"&T20,"")&" "&U20&" | Surface="&M20&" | PrimaryApp="&Q20&" | Status="&Y20&" | InstallNotes="&AC20)
V21: =IF(OR(R21="",S21=""),"",IF(U21="in",R21*S21/144,R21*S21)) | AL21: =IF(A21="","","AssetID="&A21&" | Venue="&C21&" | Zone="&D21&" | Dimensions="&R21&"x"&S21&IF(T21<>"","x"&T21,"")&" "&U21&" | Surface="&M21&" | PrimaryApp="&Q21&" | Status="&Y21&" | InstallNotes="&AC21)
V22: =IF(OR(R22="",S22=""),"",IF(U22="in",R22*S22/144,R22*S22)) | AL22: =IF(A22="","","AssetID="&A22&" | Venue="&C22&" | Zone="&D22&" | Dimensions="&R22&"x"&S22&IF(T22<>"","x"&T22,"")&" "&U22&" | Surface="&M22&" | PrimaryApp="&Q22&" | Status="&Y22&" | InstallNotes="&AC22)
V23: =IF(OR(R23="",S23=""),"",IF(U23="in",R23*S23/144,R23*S23)) | AL23: =IF(A23="","","AssetID="&A23&" | Venue="&C23&" | Zone="&D23&" | Dimensions="&R23&"x"&S23&IF(T23<>"","x"&T23,"")&" "&U23&" | Surface="&M23&" | PrimaryApp="&Q23&" | Status="&Y23&" | InstallNotes="&AC23)
V24: =IF(OR(R24="",S24=""),"",IF(U24="in",R24*S24/144,R24*S24)) | AL24: =IF(A24="","","AssetID="&A24&" | Venue="&C24&" | Zone="&D24&" | Dimensions="&R24&"x"&S24&IF(T24<>"","x"&T24,"")&" "&U24&" | Surface="&M24&" | PrimaryApp="&Q24&" | Status="&Y24&" | InstallNotes="&AC24)
V25: =IF(OR(R25="",S25=""),"",IF(U25="in",R25*S25/144,R25*S25)) | AL25: =IF(A25="","","AssetID="&A25&" | Venue="&C25&" | Zone="&D25&" | Dimensions="&R25&"x"&S25&IF(T25<>"","x"&T25,"")&" "&U25&" | Surface="&M25&" | PrimaryApp="&Q25&" | Status="&Y25&" | InstallNotes="&AC25)
... V501: =IF(OR(R501="",S501=""),"",IF(U501="in",R501*S501/144,R501*S501)) | AL501: =IF(A501="","","AssetID="&A501&" | Venue="&C501&" | Zone="&D501&" | Dimensions="&R501&"x"&S501&IF(T501<>"","x"&T501,"")&" "&U501&" | Surface="&M501&" | PrimaryApp="&Q501&" | Status="&Y501&" | InstallNotes="&AC501)

Sheet Portal_Export
A1: Asset ID | B1: Partner | C1: Venue Name | D1: Zone / Area | E1: Public Title | F1: Public Description | G1: Public Photo URL | H1: Recommended Public Applications | I1: Alternate Applications | J1: Public Use Case | K1: Visibility Tier | L1: Public Status
A2: =IF(Asset_Master!$AA2="Yes",Asset_Master!A2,"") | B2: =IF(Asset_Master!$AA2="Yes",Asset_Master!B2,"") | C2: =IF(Asset_Master!$AA2="Yes",Asset_Master!C2,"") | D2: =IF(Asset_Master!$AA2="Yes",Asset_Master!D2,"") | E2: =IF(Asset_Master!$AA2="Yes",Asset_Master!G2,"") | F2: =IF(Asset_Master!$AA2="Yes",Asset_Master!H2,"") | G2: =IF(Asset_Master!$AA2="Yes",Asset_Master!I2,"") | H2: =IF(Asset_Master!$AA2="Yes",Asset_Master!O2,"") | I2: =IF(Asset_Master!$AA2="Yes",Asset_Master!P2,"") | J2: =IF(Asset_Master!$AA2="Yes",Asset_Master!AF2,"") | K2: =IF(Asset_Master!$AA2="Yes",Asset_Master!X2,"") | L2: =IF(Asset_Master!$AA2="Yes",Asset_Master!Y2,"")
A3: =IF(Asset_Master!$AA3="Yes",Asset_Master!A3,"") | B3: =IF(Asset_Master!$AA3="Yes",Asset_Master!B3,"") | C3: =IF(Asset_Master!$AA3="Yes",Asset_Master!C3,"") | D3: =IF(Asset_Master!$AA3="Yes",Asset_Master!D3,"") | E3: =IF(Asset_Master!$AA3="Yes",Asset_Master!G3,"") | F3: =IF(Asset_Master!$AA3="Yes",Asset_Master!H3,"") | G3: =IF(Asset_Master!$AA3="Yes",Asset_Master!I3,"") | H3: =IF(Asset_Master!$AA3="Yes",Asset_Master!O3,"") | I3: =IF(Asset_Master!$AA3="Yes",Asset_Master!P3,"") | J3: =IF(Asset_Master!$AA3="Yes",Asset_Master!AF3,"") | K3: =IF(Asset_Master!$AA3="Yes",Asset_Master!X3,"") | L3: =IF(Asset_Master!$AA3="Yes",Asset_Master!Y3,"")
A4: =IF(Asset_Master!$AA4="Yes",Asset_Master!A4,"") | B4: =IF(Asset_Master!$AA4="Yes",Asset_Master!B4,"") | C4: =IF(Asset_Master!$AA4="Yes",Asset_Master!C4,"") | D4: =IF(Asset_Master!$AA4="Yes",Asset_Master!D4,"") | E4: =IF(Asset_Master!$AA4="Yes",Asset_Master!G4,"") | F4: =IF(Asset_Master!$AA4="Yes",Asset_Master!H4,"") | G4: =IF(Asset_Master!$AA4="Yes",Asset_Master!I4,"") | H4: =IF(Asset_Master!$AA4="Yes",Asset_Master!O4,"") | I4: =IF(Asset_Master!$AA4="Yes",Asset_Master!P4,"") | J4: =IF(Asset_Master!$AA4="Yes",Asset_Master!AF4,"") | K4: =IF(Asset_Master!$AA4="Yes",Asset_Master!X4,"") | L4: =IF(Asset_Master!$AA4="Yes",Asset_Master!Y4,"")
A5: =IF(Asset_Master!$AA5="Yes",Asset_Master!A5,"") | B5: =IF(Asset_Master!$AA5="Yes",Asset_Master!B5,"") | C5: =IF(Asset_Master!$AA5="Yes",Asset_Master!C5,"") | D5: =IF(Asset_Master!$AA5="Yes",Asset_Master!D5,"") | E5: =IF(Asset_Master!$AA5="Yes",Asset_Master!G5,"") | F5: =IF(Asset_Master!$AA5="Yes",Asset_Master!H5,"") | G5: =IF(Asset_Master!$AA5="Yes",Asset_Master!I5,"") | H5: =IF(Asset_Master!$AA5="Yes",Asset_Master!O5,"") | I5: =IF(Asset_Master!$AA5="Yes",Asset_Master!P5,"") | J5: =IF(Asset_Master!$AA5="Yes",Asset_Master!AF5,"") | K5: =IF(Asset_Master!$AA5="Yes",Asset_Master!X5,"") | L5: =IF(Asset_Master!$AA5="Yes",Asset_Master!Y5,"")
A6: =IF(Asset_Master!$AA6="Yes",Asset_Master!A6,"") | B6: =IF(Asset_Master!$AA6="Yes",Asset_Master!B6,"") | C6: =IF(Asset_Master!$AA6="Yes",Asset_Master!C6,"") | D6: =IF(Asset_Master!$AA6="Yes",Asset_Master!D6,"") | E6: =IF(Asset_Master!$AA6="Yes",Asset_Master!G6,"") | F6: =IF(Asset_Master!$AA6="Yes",Asset_Master!H6,"") | G6: =IF(Asset_Master!$AA6="Yes",Asset_Master!I6,"") | H6: =IF(Asset_Master!$AA6="Yes",Asset_Master!O6,"") | I6: =IF(Asset_Master!$AA6="Yes",Asset_Master!P6,"") | J6: =IF(Asset_Master!$AA6="Yes",Asset_Master!AF6,"") | K6: =IF(Asset_Master!$AA6="Yes",Asset_Master!X6,"") | L6: =IF(Asset_Master!$AA6="Yes",Asset_Master!Y6,"")
A7: =IF(Asset_Master!$AA7="Yes",Asset_Master!A7,"") | B7: =IF(Asset_Master!$AA7="Yes",Asset_Master!B7,"") | C7: =IF(Asset_Master!$AA7="Yes",Asset_Master!C7,"") | D7: =IF(Asset_Master!$AA7="Yes",Asset_Master!D7,"") | E7: =IF(Asset_Master!$AA7="Yes",Asset_Master!G7,"") | F7: =IF(Asset_Master!$AA7="Yes",Asset_Master!H7,"") | G7: =IF(Asset_Master!$AA7="Yes",Asset_Master!I7,"") | H7: =IF(Asset_Master!$AA7="Yes",Asset_Master!O7,"") | I7: =IF(Asset_Master!$AA7="Yes",Asset_Master!P7,"") | J7: =IF(Asset_Master!$AA7="Yes",Asset_Master!AF7,"") | K7: =IF(Asset_Master!$AA7="Yes",Asset_Master!X7,"") | L7: =IF(Asset_Master!$AA7="Yes",Asset_Master!Y7,"")
A8: =IF(Asset_Master!$AA8="Yes",Asset_Master!A8,"") | B8: =IF(Asset_Master!$AA8="Yes",Asset_Master!B8,"") | C8: =IF(Asset_Master!$AA8="Yes",Asset_Master!C8,"") | D8: =IF(Asset_Master!$AA8="Yes",Asset_Master!D8,"") | E8: =IF(Asset_Master!$AA8="Yes",Asset_Master!G8,"") | F8: =IF(Asset_Master!$AA8="Yes",Asset_Master!H8,"") | G8: =IF(Asset_Master!$AA8="Yes",Asset_Master!I8,"") | H8: =IF(Asset_Master!$AA8="Yes",Asset_Master!O8,"") | I8: =IF(Asset_Master!$AA8="Yes",Asset_Master!P8,"") | J8: =IF(Asset_Master!$AA8="Yes",Asset_Master!AF8,"") | K8: =IF(Asset_Master!$AA8="Yes",Asset_Master!X8,"") | L8: =IF(Asset_Master!$AA8="Yes",Asset_Master!Y8,"")
A9: =IF(Asset_Master!$AA9="Yes",Asset_Master!A9,"") | B9: =IF(Asset_Master!$AA9="Yes",Asset_Master!B9,"") | C9: =IF(Asset_Master!$AA9="Yes",Asset_Master!C9,"") | D9: =IF(Asset_Master!$AA9="Yes",Asset_Master!D9,"") | E9: =IF(Asset_Master!$AA9="Yes",Asset_Master!G9,"") | F9: =IF(Asset_Master!$AA9="Yes",Asset_Master!H9,"") | G9: =IF(Asset_Master!$AA9="Yes",Asset_Master!I9,"") | H9: =IF(Asset_Master!$AA9="Yes",Asset_Master!O9,"") | I9: =IF(Asset_Master!$AA9="Yes",Asset_Master!P9,"") | J9: =IF(Asset_Master!$AA9="Yes",Asset_Master!AF9,"") | K9: =IF(Asset_Master!$AA9="Yes",Asset_Master!X9,"") | L9: =IF(Asset_Master!$AA9="Yes",Asset_Master!Y9,"")
A10: =IF(Asset_Master!$AA10="Yes",Asset_Master!A10,"") | B10: =IF(Asset_Master!$AA10="Yes",Asset_Master!B10,"") | C10: =IF(Asset_Master!$AA10="Yes",Asset_Master!C10,"") | D10: =IF(Asset_Master!$AA10="Yes",Asset_Master!D10,"") | E10: =IF(Asset_Master!$AA10="Yes",Asset_Master!G10,"") | F10: =IF(Asset_Master!$AA10="Yes",Asset_Master!H10,"") | G10: =IF(Asset_Master!$AA10="Yes",Asset_Master!I10,"") | H10: =IF(Asset_Master!$AA10="Yes",Asset_Master!O10,"") | I10: =IF(Asset_Master!$AA10="Yes",Asset_Master!P10,"") | J10: =IF(Asset_Master!$AA10="Yes",Asset_Master!AF10,"") | K10: =IF(Asset_Master!$AA10="Yes",Asset_Master!X10,"") | L10: =IF(Asset_Master!$AA10="Yes",Asset_Master!Y10,"")
A11: =IF(Asset_Master!$AA11="Yes",Asset_Master!A11,"") | B11: =IF(Asset_Master!$AA11="Yes",Asset_Master!B11,"") | C11: =IF(Asset_Master!$AA11="Yes",Asset_Master!C11,"") | D11: =IF(Asset_Master!$AA11="Yes",Asset_Master!D11,"") | E11: =IF(Asset_Master!$AA11="Yes",Asset_Master!G11,"") | F11: =IF(Asset_Master!$AA11="Yes",Asset_Master!H11,"") | G11: =IF(Asset_Master!$AA11="Yes",Asset_Master!I11,"") | H11: =IF(Asset_Master!$AA11="Yes",Asset_Master!O11,"") | I11: =IF(Asset_Master!$AA11="Yes",Asset_Master!P11,"") | J11: =IF(Asset_Master!$AA11="Yes",Asset_Master!AF11,"") | K11: =IF(Asset_Master!$AA11="Yes",Asset_Master!X11,"") | L11: =IF(Asset_Master!$AA11="Yes",Asset_Master!Y11,"")
A12: =IF(Asset_Master!$AA12="Yes",Asset_Master!A12,"") | B12: =IF(Asset_Master!$AA12="Yes",Asset_Master!B12,"") | C12: =IF(Asset_Master!$AA12="Yes",Asset_Master!C12,"") | D12: =IF(Asset_Master!$AA12="Yes",Asset_Master!D12,"") | E12: =IF(Asset_Master!$AA12="Yes",Asset_Master!G12,"") | F12: =IF(Asset_Master!$AA12="Yes",Asset_Master!H12,"") | G12: =IF(Asset_Master!$AA12="Yes",Asset_Master!I12,"") | H12: =IF(Asset_Master!$AA12="Yes",Asset_Master!O12,"") | I12: =IF(Asset_Master!$AA12="Yes",Asset_Master!P12,"") | J12: =IF(Asset_Master!$AA12="Yes",Asset_Master!AF12,"") | K12: =IF(Asset_Master!$AA12="Yes",Asset_Master!X12,"") | L12: =IF(Asset_Master!$AA12="Yes",Asset_Master!Y12,"")
A13: =IF(Asset_Master!$AA13="Yes",Asset_Master!A13,"") | B13: =IF(Asset_Master!$AA13="Yes",Asset_Master!B13,"") | C13: =IF(Asset_Master!$AA13="Yes",Asset_Master!C13,"") | D13: =IF(Asset_Master!$AA13="Yes",Asset_Master!D13,"") | E13: =IF(Asset_Master!$AA13="Yes",Asset_Master!G13,"") | F13: =IF(Asset_Master!$AA13="Yes",Asset_Master!H13,"") | G13: =IF(Asset_Master!$AA13="Yes",Asset_Master!I13,"") | H13: =IF(Asset_Master!$AA13="Yes",Asset_Master!O13,"") | I13: =IF(Asset_Master!$AA13="Yes",Asset_Master!P13,"") | J13: =IF(Asset_Master!$AA13="Yes",Asset_Master!AF13,"") | K13: =IF(Asset_Master!$AA13="Yes",Asset_Master!X13,"") | L13: =IF(Asset_Master!$AA13="Yes",Asset_Master!Y13,"")
... A501: =IF(Asset_Master!$AA501="Yes",Asset_Master!A501,"") | B501: =IF(Asset_Master!$AA501="Yes",Asset_Master!B501,"") | C501: =IF(Asset_Master!$AA501="Yes",Asset_Master!C501,"") | D501: =IF(Asset_Master!$AA501="Yes",Asset_Master!D501,"") | E501: =IF(Asset_Master!$AA501="Yes",Asset_Master!G501,"") | F501: =IF(Asset_Master!$AA501="Yes",Asset_Master!H501,"") | G501: =IF(Asset_Master!$AA501="Yes",Asset_Master!I501,"") | H501: =IF(Asset_Master!$AA501="Yes",Asset_Master!O501,"") | I501: =IF(Asset_Master!$AA501="Yes",Asset_Master!P501,"") | J501: =IF(Asset_Master!$AA501="Yes",Asset_Master!AF501,"") | K501: =IF(Asset_Master!$AA501="Yes",Asset_Master!X501,"") | L501: =IF(Asset_Master!$AA501="Yes",Asset_Master!Y501,"")

Sheet Internal_Intake_Email
A1: Asset ID | B1: Public Title | C1: Venue Name | D1: Zone / Area | E1: Selected Application | F1: Design Needed? | G1: Public Photo URL | H1: Internal Marked Photo URL | I1: Length | J1: Width | K1: Height | L1: Measurement Unit | M1: Sq Ft | N1: Surface Material | O1: Install Notes | P1: Production Notes | Q1: NetSuite Item Name | R1: NetSuite Category | S1: Backend Hidden Payload Preview
A2: =IF(Asset_Master!$AA2="Yes",Asset_Master!A2,"") | B2: =IF(Asset_Master!$AA2="Yes",Asset_Master!G2,"") | C2: =IF(Asset_Master!$AA2="Yes",Asset_Master!C2,"") | D2: =IF(Asset_Master!$AA2="Yes",Asset_Master!D2,"") | E2: =IF(Asset_Master!$AA2="Yes",Asset_Master!Q2,"") | F2: =IF(Asset_Master!$AA2="Yes",Asset_Master!AE2,"") | G2: =IF(Asset_Master!$AA2="Yes",Asset_Master!I2,"") | H2: =IF(Asset_Master!$AA2="Yes",Asset_Master!J2,"") | I2: =IF(Asset_Master!$AA2="Yes",Asset_Master!R2,"") | J2: =IF(Asset_Master!$AA2="Yes",Asset_Master!S2,"") | K2: =IF(Asset_Master!$AA2="Yes",IF(Asset_Master!T2="","",Asset_Master!T2),"") | L2: =IF(Asset_Master!$AA2="Yes",Asset_Master!U2,"") | M2: =IF(Asset_Master!$AA2="Yes",Asset_Master!V2,"") | N2: =IF(Asset_Master!$AA2="Yes",Asset_Master!M2,"") | O2: =IF(Asset_Master!$AA2="Yes",Asset_Master!AC2,"") | P2: =IF(Asset_Master!$AA2="Yes",Asset_Master!AD2,"") | Q2: =IF(Asset_Master!$AA2="Yes",Asset_Master!AG2,"") | R2: =IF(Asset_Master!$AA2="Yes",Asset_Master!AH2,"") | S2: =IF(Asset_Master!$AA2="Yes",Asset_Master!AL2,"")
A3: =IF(Asset_Master!$AA3="Yes",Asset_Master!A3,"") | B3: =IF(Asset_Master!$AA3="Yes",Asset_Master!G3,"") | C3: =IF(Asset_Master!$AA3="Yes",Asset_Master!C3,"") | D3: =IF(Asset_Master!$AA3="Yes",Asset_Master!D3,"") | E3: =IF(Asset_Master!$AA3="Yes",Asset_Master!Q3,"") | F3: =IF(Asset_Master!$AA3="Yes",Asset_Master!AE3,"") | G3: =IF(Asset_Master!$AA3="Yes",Asset_Master!I3,"") | H3: =IF(Asset_Master!$AA3="Yes",Asset_Master!J3,"") | I3: =IF(Asset_Master!$AA3="Yes",Asset_Master!R3,"") | J3: =IF(Asset_Master!$AA3="Yes",Asset_Master!S3,"") | K3: =IF(Asset_Master!$AA3="Yes",IF(Asset_Master!T3="","",Asset_Master!T3),"") | L3: =IF(Asset_Master!$AA3="Yes",Asset_Master!U3,"") | M3: =IF(Asset_Master!$AA3="Yes",Asset_Master!V3,"") | N3: =IF(Asset_Master!$AA3="Yes",Asset_Master!M3,"") | O3: =IF(Asset_Master!$AA3="Yes",Asset_Master!AC3,"") | P3: =IF(Asset_Master!$AA3="Yes",Asset_Master!AD3,"") | Q3: =IF(Asset_Master!$AA3="Yes",Asset_Master!AG3,"") | R3: =IF(Asset_Master!$AA3="Yes",Asset_Master!AH3,"") | S3: =IF(Asset_Master!$AA3="Yes",Asset_Master!AL3,"")
A4: =IF(Asset_Master!$AA4="Yes",Asset_Master!A4,"") | B4: =IF(Asset_Master!$AA4="Yes",Asset_Master!G4,"") | C4: =IF(Asset_Master!$AA4="Yes",Asset_Master!C4,"") | D4: =IF(Asset_Master!$AA4="Yes",Asset_Master!D4,"") | E4: =IF(Asset_Master!$AA4="Yes",Asset_Master!Q4,"") | F4: =IF(Asset_Master!$AA4="Yes",Asset_Master!AE4,"") | G4: =IF(Asset_Master!$AA4="Yes",Asset_Master!I4,"") | H4: =IF(Asset_Master!$AA4="Yes",Asset_Master!J4,"") | I4: =IF(Asset_Master!$AA4="Yes",Asset_Master!R4,"") | J4: =IF(Asset_Master!$AA4="Yes",Asset_Master!S4,"") | K4: =IF(Asset_Master!$AA4="Yes",IF(Asset_Master!T4="","",Asset_Master!T4),"") | L4: =IF(Asset_Master!$AA4="Yes",Asset_Master!U4,"") | M4: =IF(Asset_Master!$AA4="Yes",Asset_Master!V4,"") | N4: =IF(Asset_Master!$AA4="Yes",Asset_Master!M4,"") | O4: =IF(Asset_Master!$AA4="Yes",Asset_Master!AC4,"") | P4: =IF(Asset_Master!$AA4="Yes",Asset_Master!AD4,"") | Q4: =IF(Asset_Master!$AA4="Yes",Asset_Master!AG4,"") | R4: =IF(Asset_Master!$AA4="Yes",Asset_Master!AH4,"") | S4: =IF(Asset_Master!$AA4="Yes",Asset_Master!AL4,"")
A5: =IF(Asset_Master!$AA5="Yes",Asset_Master!A5,"") | B5: =IF(Asset_Master!$AA5="Yes",Asset_Master!G5,"") | C5: =IF(Asset_Master!$AA5="Yes",Asset_Master!C5,"") | D5: =IF(Asset_Master!$AA5="Yes",Asset_Master!D5,"") | E5: =IF(Asset_Master!$AA5="Yes",Asset_Master!Q5,"") | F5: =IF(Asset_Master!$AA5="Yes",Asset_Master!AE5,"") | G5: =IF(Asset_Master!$AA5="Yes",Asset_Master!I5,"") | H5: =IF(Asset_Master!$AA5="Yes",Asset_Master!J5,"") | I5: =IF(Asset_Master!$AA5="Yes",Asset_Master!R5,"") | J5: =IF(Asset_Master!$AA5="Yes",Asset_Master!S5,"") | K5: =IF(Asset_Master!$AA5="Yes",IF(Asset_Master!T5="","",Asset_Master!T5),"") | L5: =IF(Asset_Master!$AA5="Yes",Asset_Master!U5,"") | M5: =IF(Asset_Master!$AA5="Yes",Asset_Master!V5,"") | N5: =IF(Asset_Master!$AA5="Yes",Asset_Master!M5,"") | O5: =IF(Asset_Master!$AA5="Yes",Asset_Master!AC5,"") | P5: =IF(Asset_Master!$AA5="Yes",Asset_Master!AD5,"") | Q5: =IF(Asset_Master!$AA5="Yes",Asset_Master!AG5,"") | R5: =IF(Asset_Master!$AA5="Yes",Asset_Master!AH5,"") | S5: =IF(Asset_Master!$AA5="Yes",Asset_Master!AL5,"")
A6: =IF(Asset_Master!$AA6="Yes",Asset_Master!A6,"") | B6: =IF(Asset_Master!$AA6="Yes",Asset_Master!G6,"") | C6: =IF(Asset_Master!$AA6="Yes",Asset_Master!C6,"") | D6: =IF(Asset_Master!$AA6="Yes",Asset_Master!D6,"") | E6: =IF(Asset_Master!$AA6="Yes",Asset_Master!Q6,"") | F6: =IF(Asset_Master!$AA6="Yes",Asset_Master!AE6,"") | G6: =IF(Asset_Master!$AA6="Yes",Asset_Master!I6,"") | H6: =IF(Asset_Master!$AA6="Yes",Asset_Master!J6,"") | I6: =IF(Asset_Master!$AA6="Yes",Asset_Master!R6,"") | J6: =IF(Asset_Master!$AA6="Yes",Asset_Master!S6,"") | K6: =IF(Asset_Master!$AA6="Yes",IF(Asset_Master!T6="","",Asset_Master!T6),"") | L6: =IF(Asset_Master!$AA6="Yes",Asset_Master!U6,"") | M6: =IF(Asset_Master!$AA6="Yes",Asset_Master!V6,"") | N6: =IF(Asset_Master!$AA6="Yes",Asset_Master!M6,"") | O6: =IF(Asset_Master!$AA6="Yes",Asset_Master!AC6,"") | P6: =IF(Asset_Master!$AA6="Yes",Asset_Master!AD6,"") | Q6: =IF(Asset_Master!$AA6="Yes",Asset_Master!AG6,"") | R6: =IF(Asset_Master!$AA6="Yes",Asset_Master!AH6,"") | S6: =IF(Asset_Master!$AA6="Yes",Asset_Master!AL6,"")
A7: =IF(Asset_Master!$AA7="Yes",Asset_Master!A7,"") | B7: =IF(Asset_Master!$AA7="Yes",Asset_Master!G7,"") | C7: =IF(Asset_Master!$AA7="Yes",Asset_Master!C7,"") | D7: =IF(Asset_Master!$AA7="Yes",Asset_Master!D7,"") | E7: =IF(Asset_Master!$AA7="Yes",Asset_Master!Q7,"") | F7: =IF(Asset_Master!$AA7="Yes",Asset_Master!AE7,"") | G7: =IF(Asset_Master!$AA7="Yes",Asset_Master!I7,"") | H7: =IF(Asset_Master!$AA7="Yes",Asset_Master!J7,"") | I7: =IF(Asset_Master!$AA7="Yes",Asset_Master!R7,"") | J7: =IF(Asset_Master!$AA7="Yes",Asset_Master!S7,"") | K7: =IF(Asset_Master!$AA7="Yes",IF(Asset_Master!T7="","",Asset_Master!T7),"") | L7: =IF(Asset_Master!$AA7="Yes",Asset_Master!U7,"") | M7: =IF(Asset_Master!$AA7="Yes",Asset_Master!V7,"") | N7: =IF(Asset_Master!$AA7="Yes",Asset_Master!M7,"") | O7: =IF(Asset_Master!$AA7="Yes",Asset_Master!AC7,"") | P7: =IF(Asset_Master!$AA7="Yes",Asset_Master!AD7,"") | Q7: =IF(Asset_Master!$AA7="Yes",Asset_Master!AG7,"") | R7: =IF(Asset_Master!$AA7="Yes",Asset_Master!AH7,"") | S7: =IF(Asset_Master!$AA7="Yes",Asset_Master!AL7,"")
A8: =IF(Asset_Master!$AA8="Yes",Asset_Master!A8,"") | B8: =IF(Asset_Master!$AA8="Yes",Asset_Master!G8,"") | C8: =IF(Asset_Master!$AA8="Yes",Asset_Master!C8,"") | D8: =IF(Asset_Master!$AA8="Yes",Asset_Master!D8,"") | E8: =IF(Asset_Master!$AA8="Yes",Asset_Master!Q8,"") | F8: =IF(Asset_Master!$AA8="Yes",Asset_Master!AE8,"") | G8: =IF(Asset_Master!$AA8="Yes",Asset_Master!I8,"") | H8: =IF(Asset_Master!$AA8="Yes",Asset_Master!J8,"") | I8: =IF(Asset_Master!$AA8="Yes",Asset_Master!R8,"") | J8: =IF(Asset_Master!$AA8="Yes",Asset_Master!S8,"") | K8: =IF(Asset_Master!$AA8="Yes",IF(Asset_Master!T8="","",Asset_Master!T8),"") | L8: =IF(Asset_Master!$AA8="Yes",Asset_Master!U8,"") | M8: =IF(Asset_Master!$AA8="Yes",Asset_Master!V8,"") | N8: =IF(Asset_Master!$AA8="Yes",Asset_Master!M8,"") | O8: =IF(Asset_Master!$AA8="Yes",Asset_Master!AC8,"") | P8: =IF(Asset_Master!$AA8="Yes",Asset_Master!AD8,"") | Q8: =IF(Asset_Master!$AA8="Yes",Asset_Master!AG8,"") | R8: =IF(Asset_Master!$AA8="Yes",Asset_Master!AH8,"") | S8: =IF(Asset_Master!$AA8="Yes",Asset_Master!AL8,"")
A9: =IF(Asset_Master!$AA9="Yes",Asset_Master!A9,"") | B9: =IF(Asset_Master!$AA9="Yes",Asset_Master!G9,"") | C9: =IF(Asset_Master!$AA9="Yes",Asset_Master!C9,"") | D9: =IF(Asset_Master!$AA9="Yes",Asset_Master!D9,"") | E9: =IF(Asset_Master!$AA9="Yes",Asset_Master!Q9,"") | F9: =IF(Asset_Master!$AA9="Yes",Asset_Master!AE9,"") | G9: =IF(Asset_Master!$AA9="Yes",Asset_Master!I9,"") | H9: =IF(Asset_Master!$AA9="Yes",Asset_Master!J9,"") | I9: =IF(Asset_Master!$AA9="Yes",Asset_Master!R9,"") | J9: =IF(Asset_Master!$AA9="Yes",Asset_Master!S9,"") | K9: =IF(Asset_Master!$AA9="Yes",IF(Asset_Master!T9="","",Asset_Master!T9),"") | L9: =IF(Asset_Master!$AA9="Yes",Asset_Master!U9,"") | M9: =IF(Asset_Master!$AA9="Yes",Asset_Master!V9,"") | N9: =IF(Asset_Master!$AA9="Yes",Asset_Master!M9,"") | O9: =IF(Asset_Master!$AA9="Yes",Asset_Master!AC9,"") | P9: =IF(Asset_Master!$AA9="Yes",Asset_Master!AD9,"") | Q9: =IF(Asset_Master!$AA9="Yes",Asset_Master!AG9,"") | R9: =IF(Asset_Master!$AA9="Yes",Asset_Master!AH9,"") | S9: =IF(Asset_Master!$AA9="Yes",Asset_Master!AL9,"")
A10: =IF(Asset_Master!$AA10="Yes",Asset_Master!A10,"") | B10: =IF(Asset_Master!$AA10="Yes",Asset_Master!G10,"") | C10: =IF(Asset_Master!$AA10="Yes",Asset_Master!C10,"") | D10: =IF(Asset_Master!$AA10="Yes",Asset_Master!D10,"") | E10: =IF(Asset_Master!$AA10="Yes",Asset_Master!Q10,"") | F10: =IF(Asset_Master!$AA10="Yes",Asset_Master!AE10,"") | G10: =IF(Asset_Master!$AA10="Yes",Asset_Master!I10,"") | H10: =IF(Asset_Master!$AA10="Yes",Asset_Master!J10,"") | I10: =IF(Asset_Master!$AA10="Yes",Asset_Master!R10,"") | J10: =IF(Asset_Master!$AA10="Yes",Asset_Master!S10,"") | K10: =IF(Asset_Master!$AA10="Yes",IF(Asset_Master!T10="","",Asset_Master!T10),"") | L10: =IF(Asset_Master!$AA10="Yes",Asset_Master!U10,"") | M10: =IF(Asset_Master!$AA10="Yes",Asset_Master!V10,"") | N10: =IF(Asset_Master!$AA10="Yes",Asset_Master!M10,"") | O10: =IF(Asset_Master!$AA10="Yes",Asset_Master!AC10,"") | P10: =IF(Asset_Master!$AA10="Yes",Asset_Master!AD10,"") | Q10: =IF(Asset_Master!$AA10="Yes",Asset_Master!AG10,"") | R10: =IF(Asset_Master!$AA10="Yes",Asset_Master!AH10,"") | S10: =IF(Asset_Master!$AA10="Yes",Asset_Master!AL10,"")
A11: =IF(Asset_Master!$AA11="Yes",Asset_Master!A11,"") | B11: =IF(Asset_Master!$AA11="Yes",Asset_Master!G11,"") | C11: =IF(Asset_Master!$AA11="Yes",Asset_Master!C11,"") | D11: =IF(Asset_Master!$AA11="Yes",Asset_Master!D11,"") | E11: =IF(Asset_Master!$AA11="Yes",Asset_Master!Q11,"") | F11: =IF(Asset_Master!$AA11="Yes",Asset_Master!AE11,"") | G11: =IF(Asset_Master!$AA11="Yes",Asset_Master!I11,"") | H11: =IF(Asset_Master!$AA11="Yes",Asset_Master!J11,"") | I11: =IF(Asset_Master!$AA11="Yes",Asset_Master!R11,"") | J11: =IF(Asset_Master!$AA11="Yes",Asset_Master!S11,"") | K11: =IF(Asset_Master!$AA11="Yes",IF(Asset_Master!T11="","",Asset_Master!T11),"") | L11: =IF(Asset_Master!$AA11="Yes",Asset_Master!U11,"") | M11: =IF(Asset_Master!$AA11="Yes",Asset_Master!V11,"") | N11: =IF(Asset_Master!$AA11="Yes",Asset_Master!M11,"") | O11: =IF(Asset_Master!$AA11="Yes",Asset_Master!AC11,"") | P11: =IF(Asset_Master!$AA11="Yes",Asset_Master!AD11,"") | Q11: =IF(Asset_Master!$AA11="Yes",Asset_Master!AG11,"") | R11: =IF(Asset_Master!$AA11="Yes",Asset_Master!AH11,"") | S11: =IF(Asset_Master!$AA11="Yes",Asset_Master!AL11,"")
A12: =IF(Asset_Master!$AA12="Yes",Asset_Master!A12,"") | B12: =IF(Asset_Master!$AA12="Yes",Asset_Master!G12,"") | C12: =IF(Asset_Master!$AA12="Yes",Asset_Master!C12,"") | D12: =IF(Asset_Master!$AA12="Yes",Asset_Master!D12,"") | E12: =IF(Asset_Master!$AA12="Yes",Asset_Master!Q12,"") | F12: =IF(Asset_Master!$AA12="Yes",Asset_Master!AE12,"") | G12: =IF(Asset_Master!$AA12="Yes",Asset_Master!I12,"") | H12: =IF(Asset_Master!$AA12="Yes",Asset_Master!J12,"") | I12: =IF(Asset_Master!$AA12="Yes",Asset_Master!R12,"") | J12: =IF(Asset_Master!$AA12="Yes",Asset_Master!S12,"") | K12: =IF(Asset_Master!$AA12="Yes",IF(Asset_Master!T12="","",Asset_Master!T12),"") | L12: =IF(Asset_Master!$AA12="Yes",Asset_Master!U12,"") | M12: =IF(Asset_Master!$AA12="Yes",Asset_Master!V12,"") | N12: =IF(Asset_Master!$AA12="Yes",Asset_Master!M12,"") | O12: =IF(Asset_Master!$AA12="Yes",Asset_Master!AC12,"") | P12: =IF(Asset_Master!$AA12="Yes",Asset_Master!AD12,"") | Q12: =IF(Asset_Master!$AA12="Yes",Asset_Master!AG12,"") | R12: =IF(Asset_Master!$AA12="Yes",Asset_Master!AH12,"") | S12: =IF(Asset_Master!$AA12="Yes",Asset_Master!AL12,"")
A13: =IF(Asset_Master!$AA13="Yes",Asset_Master!A13,"") | B13: =IF(Asset_Master!$AA13="Yes",Asset_Master!G13,"") | C13: =IF(Asset_Master!$AA13="Yes",Asset_Master!C13,"") | D13: =IF(Asset_Master!$AA13="Yes",Asset_Master!D13,"") | E13: =IF(Asset_Master!$AA13="Yes",Asset_Master!Q13,"") | F13: =IF(Asset_Master!$AA13="Yes",Asset_Master!AE13,"") | G13: =IF(Asset_Master!$AA13="Yes",Asset_Master!I13,"") | H13: =IF(Asset_Master!$AA13="Yes",Asset_Master!J13,"") | I13: =IF(Asset_Master!$AA13="Yes",Asset_Master!R13,"") | J13: =IF(Asset_Master!$AA13="Yes",Asset_Master!S13,"") | K13: =IF(Asset_Master!$AA13="Yes",IF(Asset_Master!T13="","",Asset_Master!T13),"") | L13: =IF(Asset_Master!$AA13="Yes",Asset_Master!U13,"") | M13: =IF(Asset_Master!$AA13="Yes",Asset_Master!V13,"") | N13: =IF(Asset_Master!$AA13="Yes",Asset_Master!M13,"") | O13: =IF(Asset_Master!$AA13="Yes",Asset_Master!AC13,"") | P13: =IF(Asset_Master!$AA13="Yes",Asset_Master!AD13,"") | Q13: =IF(Asset_Master!$AA13="Yes",Asset_Master!AG13,"") | R13: =IF(Asset_Master!$AA13="Yes",Asset_Master!AH13,"") | S13: =IF(Asset_Master!$AA13="Yes",Asset_Master!AL13,"")
... A501: =IF(Asset_Master!$AA501="Yes",Asset_Master!A501,"") | B501: =IF(Asset_Master!$AA501="Yes",Asset_Master!G501,"") | C501: =IF(Asset_Master!$AA501="Yes",Asset_Master!C501,"") | D501: =IF(Asset_Master!$AA501="Yes",Asset_Master!D501,"") | E501: =IF(Asset_Master!$AA501="Yes",Asset_Master!Q501,"") | F501: =IF(Asset_Master!$AA501="Yes",Asset_Master!AE501,"") | G501: =IF(Asset_Master!$AA501="Yes",Asset_Master!I501,"") | H501: =IF(Asset_Master!$AA501="Yes",Asset_Master!J501,"") | I501: =IF(Asset_Master!$AA501="Yes",Asset_Master!R501,"") | J501: =IF(Asset_Master!$AA501="Yes",Asset_Master!S501,"") | K501: =IF(Asset_Master!$AA501="Yes",IF(Asset_Master!T501="","",Asset_Master!T501),"") | L501: =IF(Asset_Master!$AA501="Yes",Asset_Master!U501,"") | M501: =IF(Asset_Master!$AA501="Yes",Asset_Master!V501,"") | N501: =IF(Asset_Master!$AA501="Yes",Asset_Master!M501,"") | O501: =IF(Asset_Master!$AA501="Yes",Asset_Master!AC501,"") | P501: =IF(Asset_Master!$AA501="Yes",Asset_Master!AD501,"") | Q501: =IF(Asset_Master!$AA501="Yes",Asset_Master!AG501,"") | R501: =IF(Asset_Master!$AA501="Yes",Asset_Master!AH501,"") | S501: =IF(Asset_Master!$AA501="Yes",Asset_Master!AL501,"")

Sheet NetSuite_Export
A1: External ID | B1: Item Name | C1: Display Name | D1: Partner | E1: Venue Name | F1: Zone / Area | G1: Asset Type | H1: Surface Material | I1: Length | J1: Width | K1: Height | L1: Unit | M1: Sq Ft | N1: Primary Recommended Application | O1: Status | P1: Description | Q1: Internal Notes | R1: Source Asset ID
A2: =IF(Asset_Master!$AB2="Yes",Asset_Master!A2,"") | B2: =IF(Asset_Master!$AB2="Yes",Asset_Master!AG2,"") | C2: =IF(Asset_Master!$AB2="Yes",Asset_Master!G2,"") | D2: =IF(Asset_Master!$AB2="Yes",Asset_Master!B2,"") | E2: =IF(Asset_Master!$AB2="Yes",Asset_Master!C2,"") | F2: =IF(Asset_Master!$AB2="Yes",Asset_Master!D2,"") | G2: =IF(Asset_Master!$AB2="Yes",Asset_Master!F2,"") | H2: =IF(Asset_Master!$AB2="Yes",Asset_Master!M2,"") | I2: =IF(Asset_Master!$AB2="Yes",Asset_Master!R2,"") | J2: =IF(Asset_Master!$AB2="Yes",Asset_Master!S2,"") | K2: =IF(Asset_Master!$AB2="Yes",IF(Asset_Master!T2="","",Asset_Master!T2),"") | L2: =IF(Asset_Master!$AB2="Yes",Asset_Master!U2,"") | M2: =IF(Asset_Master!$AB2="Yes",Asset_Master!V2,"") | N2: =IF(Asset_Master!$AB2="Yes",Asset_Master!Q2,"") | O2: =IF(Asset_Master!$AB2="Yes",Asset_Master!Y2,"") | P2: =IF(Asset_Master!$AB2="Yes",Asset_Master!H2,"") | Q2: =IF(Asset_Master!$AB2="Yes",Asset_Master!AC2&" | "&Asset_Master!AD2,"") | R2: =IF(Asset_Master!$AB2="Yes",Asset_Master!A2,"")
A3: =IF(Asset_Master!$AB3="Yes",Asset_Master!A3,"") | B3: =IF(Asset_Master!$AB3="Yes",Asset_Master!AG3,"") | C3: =IF(Asset_Master!$AB3="Yes",Asset_Master!G3,"") | D3: =IF(Asset_Master!$AB3="Yes",Asset_Master!B3,"") | E3: =IF(Asset_Master!$AB3="Yes",Asset_Master!C3,"") | F3: =IF(Asset_Master!$AB3="Yes",Asset_Master!D3,"") | G3: =IF(Asset_Master!$AB3="Yes",Asset_Master!F3,"") | H3: =IF(Asset_Master!$AB3="Yes",Asset_Master!M3,"") | I3: =IF(Asset_Master!$AB3="Yes",Asset_Master!R3,"") | J3: =IF(Asset_Master!$AB3="Yes",Asset_Master!S3,"") | K3: =IF(Asset_Master!$AB3="Yes",IF(Asset_Master!T3="","",Asset_Master!T3),"") | L3: =IF(Asset_Master!$AB3="Yes",Asset_Master!U3,"") | M3: =IF(Asset_Master!$AB3="Yes",Asset_Master!V3,"") | N3: =IF(Asset_Master!$AB3="Yes",Asset_Master!Q3,"") | O3: =IF(Asset_Master!$AB3="Yes",Asset_Master!Y3,"") | P3: =IF(Asset_Master!$AB3="Yes",Asset_Master!H3,"") | Q3: =IF(Asset_Master!$AB3="Yes",Asset_Master!AC3&" | "&Asset_Master!AD3,"") | R3: =IF(Asset_Master!$AB3="Yes",Asset_Master!A3,"")
A4: =IF(Asset_Master!$AB4="Yes",Asset_Master!A4,"") | B4: =IF(Asset_Master!$AB4="Yes",Asset_Master!AG4,"") | C4: =IF(Asset_Master!$AB4="Yes",Asset_Master!G4,"") | D4: =IF(Asset_Master!$AB4="Yes",Asset_Master!B4,"") | E4: =IF(Asset_Master!$AB4="Yes",Asset_Master!C4,"") | F4: =IF(Asset_Master!$AB4="Yes",Asset_Master!D4,"") | G4: =IF(Asset_Master!$AB4="Yes",Asset_Master!F4,"") | H4: =IF(Asset_Master!$AB4="Yes",Asset_Master!M4,"") | I4: =IF(Asset_Master!$AB4="Yes",Asset_Master!R4,"") | J4: =IF(Asset_Master!$AB4="Yes",Asset_Master!S4,"") | K4: =IF(Asset_Master!$AB4="Yes",IF(Asset_Master!T4="","",Asset_Master!T4),"") | L4: =IF(Asset_Master!$AB4="Yes",Asset_Master!U4,"") | M4: =IF(Asset_Master!$AB4="Yes",Asset_Master!V4,"") | N4: =IF(Asset_Master!$AB4="Yes",Asset_Master!Q4,"") | O4: =IF(Asset_Master!$AB4="Yes",Asset_Master!Y4,"") | P4: =IF(Asset_Master!$AB4="Yes",Asset_Master!H4,"") | Q4: =IF(Asset_Master!$AB4="Yes",Asset_Master!AC4&" | "&Asset_Master!AD4,"") | R4: =IF(Asset_Master!$AB4="Yes",Asset_Master!A4,"")
A5: =IF(Asset_Master!$AB5="Yes",Asset_Master!A5,"") | B5: =IF(Asset_Master!$AB5="Yes",Asset_Master!AG5,"") | C5: =IF(Asset_Master!$AB5="Yes",Asset_Master!G5,"") | D5: =IF(Asset_Master!$AB5="Yes",Asset_Master!B5,"") | E5: =IF(Asset_Master!$AB5="Yes",Asset_Master!C5,"") | F5: =IF(Asset_Master!$AB5="Yes",Asset_Master!D5,"") | G5: =IF(Asset_Master!$AB5="Yes",Asset_Master!F5,"") | H5: =IF(Asset_Master!$AB5="Yes",Asset_Master!M5,"") | I5: =IF(Asset_Master!$AB5="Yes",Asset_Master!R5,"") | J5: =IF(Asset_Master!$AB5="Yes",Asset_Master!S5,"") | K5: =IF(Asset_Master!$AB5="Yes",IF(Asset_Master!T5="","",Asset_Master!T5),"") | L5: =IF(Asset_Master!$AB5="Yes",Asset_Master!U5,"") | M5: =IF(Asset_Master!$AB5="Yes",Asset_Master!V5,"") | N5: =IF(Asset_Master!$AB5="Yes",Asset_Master!Q5,"") | O5: =IF(Asset_Master!$AB5="Yes",Asset_Master!Y5,"") | P5: =IF(Asset_Master!$AB5="Yes",Asset_Master!H5,"") | Q5: =IF(Asset_Master!$AB5="Yes",Asset_Master!AC5&" | "&Asset_Master!AD5,"") | R5: =IF(Asset_Master!$AB5="Yes",Asset_Master!A5,"")
A6: =IF(Asset_Master!$AB6="Yes",Asset_Master!A6,"") | B6: =IF(Asset_Master!$AB6="Yes",Asset_Master!AG6,"") | C6: =IF(Asset_Master!$AB6="Yes",Asset_Master!G6,"") | D6: =IF(Asset_Master!$AB6="Yes",Asset_Master!B6,"") | E6: =IF(Asset_Master!$AB6="Yes",Asset_Master!C6,"") | F6: =IF(Asset_Master!$AB6="Yes",Asset_Master!D6,"") | G6: =IF(Asset_Master!$AB6="Yes",Asset_Master!F6,"") | H6: =IF(Asset_Master!$AB6="Yes",Asset_Master!M6,"") | I6: =IF(Asset_Master!$AB6="Yes",Asset_Master!R6,"") | J6: =IF(Asset_Master!$AB6="Yes",Asset_Master!S6,"") | K6: =IF(Asset_Master!$AB6="Yes",IF(Asset_Master!T6="","",Asset_Master!T6),"") | L6: =IF(Asset_Master!$AB6="Yes",Asset_Master!U6,"") | M6: =IF(Asset_Master!$AB6="Yes",Asset_Master!V6,"") | N6: =IF(Asset_Master!$AB6="Yes",Asset_Master!Q6,"") | O6: =IF(Asset_Master!$AB6="Yes",Asset_Master!Y6,"") | P6: =IF(Asset_Master!$AB6="Yes",Asset_Master!H6,"") | Q6: =IF(Asset_Master!$AB6="Yes",Asset_Master!AC6&" | "&Asset_Master!AD6,"") | R6: =IF(Asset_Master!$AB6="Yes",Asset_Master!A6,"")
A7: =IF(Asset_Master!$AB7="Yes",Asset_Master!A7,"") | B7: =IF(Asset_Master!$AB7="Yes",Asset_Master!AG7,"") | C7: =IF(Asset_Master!$AB7="Yes",Asset_Master!G7,"") | D7: =IF(Asset_Master!$AB7="Yes",Asset_Master!B7,"") | E7: =IF(Asset_Master!$AB7="Yes",Asset_Master!C7,"") | F7: =IF(Asset_Master!$AB7="Yes",Asset_Master!D7,"") | G7: =IF(Asset_Master!$AB7="Yes",Asset_Master!F7,"") | H7: =IF(Asset_Master!$AB7="Yes",Asset_Master!M7,"") | I7: =IF(Asset_Master!$AB7="Yes",Asset_Master!R7,"") | J7: =IF(Asset_Master!$AB7="Yes",Asset_Master!S7,"") | K7: =IF(Asset_Master!$AB7="Yes",IF(Asset_Master!T7="","",Asset_Master!T7),"") | L7: =IF(Asset_Master!$AB7="Yes",Asset_Master!U7,"") | M7: =IF(Asset_Master!$AB7="Yes",Asset_Master!V7,"") | N7: =IF(Asset_Master!$AB7="Yes",Asset_Master!Q7,"") | O7: =IF(Asset_Master!$AB7="Yes",Asset_Master!Y7,"") | P7: =IF(Asset_Master!$AB7="Yes",Asset_Master!H7,"") | Q7: =IF(Asset_Master!$AB7="Yes",Asset_Master!AC7&" | "&Asset_Master!AD7,"") | R7: =IF(Asset_Master!$AB7="Yes",Asset_Master!A7,"")
A8: =IF(Asset_Master!$AB8="Yes",Asset_Master!A8,"") | B8: =IF(Asset_Master!$AB8="Yes",Asset_Master!AG8,"") | C8: =IF(Asset_Master!$AB8="Yes",Asset_Master!G8,"") | D8: =IF(Asset_Master!$AB8="Yes",Asset_Master!B8,"") | E8: =IF(Asset_Master!$AB8="Yes",Asset_Master!C8,"") | F8: =IF(Asset_Master!$AB8="Yes",Asset_Master!D8,"") | G8: =IF(Asset_Master!$AB8="Yes",Asset_Master!F8,"") | H8: =IF(Asset_Master!$AB8="Yes",Asset_Master!M8,"") | I8: =IF(Asset_Master!$AB8="Yes",Asset_Master!R8,"") | J8: =IF(Asset_Master!$AB8="Yes",Asset_Master!S8,"") | K8: =IF(Asset_Master!$AB8="Yes",IF(Asset_Master!T8="","",Asset_Master!T8),"") | L8: =IF(Asset_Master!$AB8="Yes",Asset_Master!U8,"") | M8: =IF(Asset_Master!$AB8="Yes",Asset_Master!V8,"") | N8: =IF(Asset_Master!$AB8="Yes",Asset_Master!Q8,"") | O8: =IF(Asset_Master!$AB8="Yes",Asset_Master!Y8,"") | P8: =IF(Asset_Master!$AB8="Yes",Asset_Master!H8,"") | Q8: =IF(Asset_Master!$AB8="Yes",Asset_Master!AC8&" | "&Asset_Master!AD8,"") | R8: =IF(Asset_Master!$AB8="Yes",Asset_Master!A8,"")
A9: =IF(Asset_Master!$AB9="Yes",Asset_Master!A9,"") | B9: =IF(Asset_Master!$AB9="Yes",Asset_Master!AG9,"") | C9: =IF(Asset_Master!$AB9="Yes",Asset_Master!G9,"") | D9: =IF(Asset_Master!$AB9="Yes",Asset_Master!B9,"") | E9: =IF(Asset_Master!$AB9="Yes",Asset_Master!C9,"") | F9: =IF(Asset_Master!$AB9="Yes",Asset_Master!D9,"") | G9: =IF(Asset_Master!$AB9="Yes",Asset_Master!F9,"") | H9: =IF(Asset_Master!$AB9="Yes",Asset_Master!M9,"") | I9: =IF(Asset_Master!$AB9="Yes",Asset_Master!R9,"") | J9: =IF(Asset_Master!$AB9="Yes",Asset_Master!S9,"") | K9: =IF(Asset_Master!$AB9="Yes",IF(Asset_Master!T9="","",Asset_Master!T9),"") | L9: =IF(Asset_Master!$AB9="Yes",Asset_Master!U9,"") | M9: =IF(Asset_Master!$AB9="Yes",Asset_Master!V9,"") | N9: =IF(Asset_Master!$AB9="Yes",Asset_Master!Q9,"") | O9: =IF(Asset_Master!$AB9="Yes",Asset_Master!Y9,"") | P9: =IF(Asset_Master!$AB9="Yes",Asset_Master!H9,"") | Q9: =IF(Asset_Master!$AB9="Yes",Asset_Master!AC9&" | "&Asset_Master!AD9,"") | R9: =IF(Asset_Master!$AB9="Yes",Asset_Master!A9,"")
A10: =IF(Asset_Master!$AB10="Yes",Asset_Master!A10,"") | B10: =IF(Asset_Master!$AB10="Yes",Asset_Master!AG10,"") | C10: =IF(Asset_Master!$AB10="Yes",Asset_Master!G10,"") | D10: =IF(Asset_Master!$AB10="Yes",Asset_Master!B10,"") | E10: =IF(Asset_Master!$AB10="Yes",Asset_Master!C10,"") | F10: =IF(Asset_Master!$AB10="Yes",Asset_Master!D10,"") | G10: =IF(Asset_Master!$AB10="Yes",Asset_Master!F10,"") | H10: =IF(Asset_Master!$AB10="Yes",Asset_Master!M10,"") | I10: =IF(Asset_Master!$AB10="Yes",Asset_Master!R10,"") | J10: =IF(Asset_Master!$AB10="Yes",Asset_Master!S10,"") | K10: =IF(Asset_Master!$AB10="Yes",IF(Asset_Master!T10="","",Asset_Master!T10),"") | L10: =IF(Asset_Master!$AB10="Yes",Asset_Master!U10,"") | M10: =IF(Asset_Master!$AB10="Yes",Asset_Master!V10,"") | N10: =IF(Asset_Master!$AB10="Yes",Asset_Master!Q10,"") | O10: =IF(Asset_Master!$AB10="Yes",Asset_Master!Y10,"") | P10: =IF(Asset_Master!$AB10="Yes",Asset_Master!H10,"") | Q10: =IF(Asset_Master!$AB10="Yes",Asset_Master!AC10&" | "&Asset_Master!AD10,"") | R10: =IF(Asset_Master!$AB10="Yes",Asset_Master!A10,"")
A11: =IF(Asset_Master!$AB11="Yes",Asset_Master!A11,"") | B11: =IF(Asset_Master!$AB11="Yes",Asset_Master!AG11,"") | C11: =IF(Asset_Master!$AB11="Yes",Asset_Master!G11,"") | D11: =IF(Asset_Master!$AB11="Yes",Asset_Master!B11,"") | E11: =IF(Asset_Master!$AB11="Yes",Asset_Master!C11,"") | F11: =IF(Asset_Master!$AB11="Yes",Asset_Master!D11,"") | G11: =IF(Asset_Master!$AB11="Yes",Asset_Master!F11,"") | H11: =IF(Asset_Master!$AB11="Yes",Asset_Master!M11,"") | I11: =IF(Asset_Master!$AB11="Yes",Asset_Master!R11,"") | J11: =IF(Asset_Master!$AB11="Yes",Asset_Master!S11,"") | K11: =IF(Asset_Master!$AB11="Yes",IF(Asset_Master!T11="","",Asset_Master!T11),"") | L11: =IF(Asset_Master!$AB11="Yes",Asset_Master!U11,"") | M11: =IF(Asset_Master!$AB11="Yes",Asset_Master!V11,"") | N11: =IF(Asset_Master!$AB11="Yes",Asset_Master!Q11,"") | O11: =IF(Asset_Master!$AB11="Yes",Asset_Master!Y11,"") | P11: =IF(Asset_Master!$AB11="Yes",Asset_Master!H11,"") | Q11: =IF(Asset_Master!$AB11="Yes",Asset_Master!AC11&" | "&Asset_Master!AD11,"") | R11: =IF(Asset_Master!$AB11="Yes",Asset_Master!A11,"")
A12: =IF(Asset_Master!$AB12="Yes",Asset_Master!A12,"") | B12: =IF(Asset_Master!$AB12="Yes",Asset_Master!AG12,"") | C12: =IF(Asset_Master!$AB12="Yes",Asset_Master!G12,"") | D12: =IF(Asset_Master!$AB12="Yes",Asset_Master!B12,"") | E12: =IF(Asset_Master!$AB12="Yes",Asset_Master!C12,"") | F12: =IF(Asset_Master!$AB12="Yes",Asset_Master!D12,"") | G12: =IF(Asset_Master!$AB12="Yes",Asset_Master!F12,"") | H12: =IF(Asset_Master!$AB12="Yes",Asset_Master!M12,"") | I12: =IF(Asset_Master!$AB12="Yes",Asset_Master!R12,"") | J12: =IF(Asset_Master!$AB12="Yes",Asset_Master!S12,"") | K12: =IF(Asset_Master!$AB12="Yes",IF(Asset_Master!T12="","",Asset_Master!T12),"") | L12: =IF(Asset_Master!$AB12="Yes",Asset_Master!U12,"") | M12: =IF(Asset_Master!$AB12="Yes",Asset_Master!V12,"") | N12: =IF(Asset_Master!$AB12="Yes",Asset_Master!Q12,"") | O12: =IF(Asset_Master!$AB12="Yes",Asset_Master!Y12,"") | P12: =IF(Asset_Master!$AB12="Yes",Asset_Master!H12,"") | Q12: =IF(Asset_Master!$AB12="Yes",Asset_Master!AC12&" | "&Asset_Master!AD12,"") | R12: =IF(Asset_Master!$AB12="Yes",Asset_Master!A12,"")
A13: =IF(Asset_Master!$AB13="Yes",Asset_Master!A13,"") | B13: =IF(Asset_Master!$AB13="Yes",Asset_Master!AG13,"") | C13: =IF(Asset_Master!$AB13="Yes",Asset_Master!G13,"") | D13: =IF(Asset_Master!$AB13="Yes",Asset_Master!B13,"") | E13: =IF(Asset_Master!$AB13="Yes",Asset_Master!C13,"") | F13: =IF(Asset_Master!$AB13="Yes",Asset_Master!D13,"") | G13: =IF(Asset_Master!$AB13="Yes",Asset_Master!F13,"") | H13: =IF(Asset_Master!$AB13="Yes",Asset_Master!M13,"") | I13: =IF(Asset_Master!$AB13="Yes",Asset_Master!R13,"") | J13: =IF(Asset_Master!$AB13="Yes",Asset_Master!S13,"") | K13: =IF(Asset_Master!$AB13="Yes",IF(Asset_Master!T13="","",Asset_Master!T13),"") | L13: =IF(Asset_Master!$AB13="Yes",Asset_Master!U13,"") | M13: =IF(Asset_Master!$AB13="Yes",Asset_Master!V13,"") | N13: =IF(Asset_Master!$AB13="Yes",Asset_Master!Q13,"") | O13: =IF(Asset_Master!$AB13="Yes",Asset_Master!Y13,"") | P13: =IF(Asset_Master!$AB13="Yes",Asset_Master!H13,"") | Q13: =IF(Asset_Master!$AB13="Yes",Asset_Master!AC13&" | "&Asset_Master!AD13,"") | R13: =IF(Asset_Master!$AB13="Yes",Asset_Master!A13,"")
